# panic 与 recover

## 触发 panic

可以通过 `panic` 函数触发：

```go
func main() {
 panic("TOMO-CAT")
 return
}

// 输出:
panic: TOMO-CAT

goroutine 1 [running]:
main.main()
        /Users/MyProject/src/main/main.go:25 +0x39

Process finished with exit code 2
```

## 捕获 panic

`recover` 函数用于终止错误，但是必须在 `defer` 函数中才能生效：

```go
defer func() {
    if r := recover(); r != nil {
        fmt.Printf("panic with unknown err: %v\n", r)
    }
}()
```

## 注意 panic 无法跨协程

需要注意的是在子协程内触发 `panic`，只能在子协程内的 `defer` 函数中捕获 `panic`，不能在外层协程里面来捕获 `panic`。

```go
func main() {
 // 在 main 函数中捕获 panic
 defer func() {
  if r := recover(); r != nil {
   fmt.Printf("panic with unknown err: %v\n", r)
  }
 }()

 // 新开子协程触发 panic 但是并没有捕获
 go func() {
  panic("TOMO-CAT")
 }()

 // sleep 一会, 否则子协程还未执行就退出 main 函数了
 time.Sleep(1 * time.Second)

 return
}

// 输出:
panic: TOMO-CAT

goroutine 5 [running]:
main.main.func2()
        /Users/MyProject/src/main/main.go:34 +0x39
created by main.main
        /Users/MyProject/src/main/main.go:33 +0x5b

Process finished with exit code 2
```